<?xml version="1.0" encoding="utf-8"?>
<robot name="go2_description" path="/home/chris/Desktop/go2/urdf/go2_description.urdf">
	<link name="base">
		<inertial>
			<origin xyz="0.021112 0 -0.005366" rpy="0 0 0"></origin>
			<mass value="6.921"></mass>
			<inertia ixx="0.02448" ixy="0.00012166" ixz="0.0014849" iyy="0.098077" iyz="-3.12E-05" izz="0.107"></inertia>
		</inertial>
		<visual>
			<origin xyz="0 0 0" rpy="0 0 0"></origin>
			<geometry>
				<mesh filename="/home/chris/Desktop/go2/dae/base.dae"></mesh>
			</geometry>
			<material name="">
				<color rgba="1 1 1 1"></color>
			</material>
		</visual>
		<collision>
			<geometry>
				<sphere radius="0.079978"></sphere>
			</geometry>
			<origin xyz="0.087307 -1e-06 -1e-05" rpy="0 0 0"></origin>
		</collision>
		<collision>
			<geometry>
				<sphere radius="0.087294"></sphere>
			</geometry>
			<origin xyz="-0.141354 -2e-06 2e-06" rpy="0 0 0"></origin>
		</collision>
		<collision>
			<geometry>
				<sphere radius="0.087296"></sphere>
			</geometry>
			<origin xyz="0.141347 0.0 -1e-06" rpy="0 0 0"></origin>
		</collision>
		<collision>
			<geometry>
				<sphere radius="0.079966"></sphere>
			</geometry>
			<origin xyz="-0.040732 -1e-06 3e-06" rpy="0 0 0"></origin>
		</collision>
		<collision>
			<geometry>
				<sphere radius="0.079965"></sphere>
			</geometry>
			<origin xyz="0.023281 1e-06 0.0" rpy="0 0 0"></origin>
		</collision>
		<collision>
			<geometry>
				<sphere radius="0.07819"></sphere>
			</geometry>
			<origin xyz="-0.099748 -3e-06 -4e-05" rpy="0 0 0"></origin>
		</collision>
	</link>
	<link name="Head_upper">
		<inertial>
			<origin xyz="0 0 0" rpy="0 0 0"></origin>
			<mass value="0.001"></mass>
			<inertia ixx="9.6e-06" ixy="0" ixz="0" iyy="9.6e-06" iyz="0" izz="9.6e-06"></inertia>
		</inertial>
		<collision>
			<geometry>
				<sphere radius="0.067268"></sphere>
			</geometry>
			<origin xyz="0.0 0.0 0.0" rpy="0 0 0"></origin>
		</collision>
	</link>
	<link name="FL_hip">
		<inertial>
			<origin xyz="-0.0054 0.00194 -0.000105" rpy="0 0 0"></origin>
			<mass value="0.678"></mass>
			<inertia ixx="0.00048" ixy="-3.01E-06" ixz="1.11E-06" iyy="0.000884" iyz="-1.42E-06" izz="0.000596"></inertia>
		</inertial>
		<visual>
			<origin xyz="0 0 0" rpy="0 0 0"></origin>
			<geometry>
				<mesh filename="/home/chris/Desktop/go2/dae/hip.dae"></mesh>
			</geometry>
			<material name="">
				<color rgba="1 1 1 1"></color>
			</material>
		</visual>
		<collision>
			<geometry>
				<sphere radius="0.050163"></sphere>
			</geometry>
			<origin xyz="2e-06 0.080001 -2e-06" rpy="0 0 0"></origin>
		</collision>
	</link>
	<link name="FL_hip_rotor">
		<inertial>
			<origin rpy="0 0 0" xyz="0.0 0.0 0.0"></origin>
			<mass value="0.089"></mass>
			<inertia ixx="0.000111842" ixy="0.0" ixz="0.0" iyy="0.000059647" iyz="0.0" izz="0.000059647"></inertia>
		</inertial>
	</link>
	<link name="FL_thigh">
		<inertial>
			<origin xyz="-0.00374 -0.0223 -0.0327" rpy="0 0 0"></origin>
			<mass value="1.152"></mass>
			<inertia ixx="0.00584" ixy="8.72E-05" ixz="-0.000289" iyy="0.0058" iyz="0.000808" izz="0.00103"></inertia>
		</inertial>
		<visual>
			<origin xyz="0 0 0" rpy="0 0 0"></origin>
			<geometry>
				<mesh filename="/home/chris/Desktop/go2/dae/thigh.dae"></mesh>
			</geometry>
			<material name="">
				<color rgba="1 1 1 1"></color>
			</material>
		</visual>
		<collision>
			<geometry>
				<sphere radius="0.025579"></sphere>
			</geometry>
			<origin xyz="4.3e-05 0.0 -0.198381" rpy="0 0 0"></origin>
		</collision>
		<collision>
			<geometry>
				<sphere radius="0.024546"></sphere>
			</geometry>
			<origin xyz="-0.001662 0.0 -0.17118699999999998" rpy="0 0 0"></origin>
		</collision>
		<collision>
			<geometry>
				<sphere radius="0.025629"></sphere>
			</geometry>
			<origin xyz="0.001044 0.0 -0.142855" rpy="0 0 0"></origin>
		</collision>
		<collision>
			<geometry>
				<sphere radius="0.025191"></sphere>
			</geometry>
			<origin xyz="-0.001831 0.0 -0.113311" rpy="0 0 0"></origin>
		</collision>
		<collision>
			<geometry>
				<sphere radius="0.025179"></sphere>
			</geometry>
			<origin xyz="0.001768 0.0 -0.083894" rpy="0 0 0"></origin>
		</collision>
		<collision>
			<geometry>
				<sphere radius="0.025668"></sphere>
			</geometry>
			<origin xyz="-0.001052 0.0 -0.054338" rpy="0 0 0"></origin>
		</collision>
		<collision>
			<geometry>
				<sphere radius="0.023307"></sphere>
			</geometry>
			<origin xyz="5.7e-05 0.0 -0.028247999999999995" rpy="0 0 0"></origin>
		</collision>
		<collision>
			<geometry>
				<sphere radius="0.024271"></sphere>
			</geometry>
			<origin xyz="0.0 -1e-06 -0.012247999999999995" rpy="0 0 0"></origin>
		</collision>
	</link>
	<link name="FL_thigh_rotor">
		<inertial>
			<origin rpy="0 0 0" xyz="0.0 0.0 0.0"></origin>
			<mass value="0.089"></mass>
			<inertia ixx="0.000059647" ixy="0.0" ixz="0.0" iyy="0.000111842" iyz="0.0" izz="0.000059647"></inertia>
		</inertial>
	</link>
	<link name="FL_calf">
		<inertial>
			<origin xyz="0.00548 -0.000975 -0.115" rpy="0 0 0"></origin>
			<mass value="0.154"></mass>
			<inertia ixx="0.00108" ixy="3.4E-07" ixz="1.72E-05" iyy="0.0011" iyz="8.28E-06" izz="3.29E-05"></inertia>
		</inertial>
		<visual>
			<origin xyz="0 0 0" rpy="0 0 0"></origin>
			<geometry>
				<mesh filename="/home/chris/Desktop/go2/dae/calf.dae"></mesh>
			</geometry>
			<material name="">
				<color rgba="1 1 1 1"></color>
			</material>
		</visual>
		<collision>
			<geometry>
				<sphere radius="0.016712"></sphere>
			</geometry>
			<origin xyz="0.018083 0.0 -0.107306" rpy="0 0 0"></origin>
		</collision>
		<collision>
			<geometry>
				<sphere radius="0.015092"></sphere>
			</geometry>
			<origin xyz="0.00033299999999999823 0.0 -0.023307999999999995" rpy="0 0 0"></origin>
		</collision>
		<collision>
			<geometry>
				<sphere radius="0.016713"></sphere>
			</geometry>
			<origin xyz="-0.0020820000000000023 0.0 -0.012694999999999998" rpy="0 0 0"></origin>
		</collision>
		<collision>
			<geometry>
				<sphere radius="0.014081"></sphere>
			</geometry>
			<origin xyz="0.013404 -1e-06 -0.085864" rpy="0 0 0"></origin>
		</collision>
		<collision>
			<geometry>
				<sphere radius="0.015153"></sphere>
			</geometry>
			<origin xyz="0.004010999999999998 0.0 -0.041257" rpy="0 0 0"></origin>
		</collision>
		<collision>
			<geometry>
				<sphere radius="0.01423"></sphere>
			</geometry>
			<origin xyz="0.016745999999999997 0.0 -0.100522" rpy="0 0 0"></origin>
		</collision>
		<collision>
			<geometry>
				<sphere radius="0.013892"></sphere>
			</geometry>
			<origin xyz="0.010446999999999998 0.0 -0.071486" rpy="0 0 0"></origin>
		</collision>
		<collision>
			<geometry>
				<sphere radius="0.014001"></sphere>
			</geometry>
			<origin xyz="0.007484999999999999 0.0 -0.057586" rpy="0 0 0"></origin>
		</collision>
	</link>
	<link name="FL_calflower">
		<collision>
			<geometry>
				<sphere radius="0.014132"></sphere>
			</geometry>
			<origin xyz="0.0 0.0 0.004524" rpy="0 0 0"></origin>
		</collision>
		<collision>
			<geometry>
				<sphere radius="0.01554"></sphere>
			</geometry>
			<origin xyz="0.0 0.0 -0.021523" rpy="0 0 0"></origin>
		</collision>
		<collision>
			<geometry>
				<sphere radius="0.013628"></sphere>
			</geometry>
			<origin xyz="-1e-06 0.0 -0.012392" rpy="0 0 0"></origin>
		</collision>
		<collision>
			<geometry>
				<sphere radius="0.015541"></sphere>
			</geometry>
			<origin xyz="0.0 0.0 0.021523" rpy="0 0 0"></origin>
		</collision>
	</link>
	<link name="FL_calflower1">
		<collision>
			<geometry>
				<sphere radius="0.02157"></sphere>
			</geometry>
			<origin xyz="0.0 1e-06 0.0" rpy="0 0 0"></origin>
		</collision>
	</link>
	<link name="FL_calf_rotor">
		<inertial>
			<origin rpy="0 0 0" xyz="0.0 0.0 0.0"></origin>
			<mass value="0.089"></mass>
			<inertia ixx="0.000059647" ixy="0.0" ixz="0.0" iyy="0.000111842" iyz="0.0" izz="0.000059647"></inertia>
		</inertial>
	</link>
	<link name="FR_hip">
		<inertial>
			<origin xyz="-0.0054 -0.00194 -0.000105" rpy="0 0 0"></origin>
			<mass value="0.678"></mass>
			<inertia ixx="0.00048" ixy="3.01E-06" ixz="1.11E-06" iyy="0.000884" iyz="1.42E-06" izz="0.000596"></inertia>
		</inertial>
		<visual>
			<origin xyz="0 0 0" rpy="3.1415 0 0"></origin>
			<geometry>
				<mesh filename="/home/chris/Desktop/go2/dae/hip.dae"></mesh>
			</geometry>
			<material name="">
				<color rgba="1 1 1 1"></color>
			</material>
		</visual>
		<collision>
			<geometry>
				<sphere radius="0.050163"></sphere>
			</geometry>
			<origin xyz="2e-06 -0.079999 -2e-06" rpy="0 0 0"></origin>
		</collision>
	</link>
	<link name="FR_hip_rotor">
		<inertial>
			<origin rpy="0 0 0" xyz="0.0 0.0 0.0"></origin>
			<mass value="0.089"></mass>
			<inertia ixx="0.000111842" ixy="0.0" ixz="0.0" iyy="0.000059647" iyz="0.0" izz="0.000059647"></inertia>
		</inertial>
	</link>
	<link name="FR_thigh">
		<inertial>
			<origin xyz="-0.00374 0.0223 -0.0327" rpy="0 0 0"></origin>
			<mass value="1.152"></mass>
			<inertia ixx="0.00584" ixy="-8.72E-05" ixz="-0.000289" iyy="0.0058" iyz="-0.000808" izz="0.00103"></inertia>
		</inertial>
		<visual>
			<origin xyz="0 0 0" rpy="0 0 0"></origin>
			<geometry>
				<mesh filename="/home/chris/Desktop/go2/dae/thigh_mirror.dae"></mesh>
			</geometry>
			<material name="">
				<color rgba="1 1 1 1"></color>
			</material>
		</visual>
		<collision>
			<geometry>
				<sphere radius="0.025579"></sphere>
			</geometry>
			<origin xyz="4.3e-05 0.0 -0.198381" rpy="0 0 0"></origin>
		</collision>
		<collision>
			<geometry>
				<sphere radius="0.024546"></sphere>
			</geometry>
			<origin xyz="-0.001662 0.0 -0.17118699999999998" rpy="0 0 0"></origin>
		</collision>
		<collision>
			<geometry>
				<sphere radius="0.025629"></sphere>
			</geometry>
			<origin xyz="0.001044 0.0 -0.142855" rpy="0 0 0"></origin>
		</collision>
		<collision>
			<geometry>
				<sphere radius="0.025191"></sphere>
			</geometry>
			<origin xyz="-0.001831 0.0 -0.113311" rpy="0 0 0"></origin>
		</collision>
		<collision>
			<geometry>
				<sphere radius="0.025179"></sphere>
			</geometry>
			<origin xyz="0.001768 0.0 -0.083894" rpy="0 0 0"></origin>
		</collision>
		<collision>
			<geometry>
				<sphere radius="0.025668"></sphere>
			</geometry>
			<origin xyz="-0.001052 0.0 -0.054338" rpy="0 0 0"></origin>
		</collision>
		<collision>
			<geometry>
				<sphere radius="0.023307"></sphere>
			</geometry>
			<origin xyz="5.7e-05 0.0 -0.028247999999999995" rpy="0 0 0"></origin>
		</collision>
		<collision>
			<geometry>
				<sphere radius="0.024271"></sphere>
			</geometry>
			<origin xyz="0.0 -1e-06 -0.012247999999999995" rpy="0 0 0"></origin>
		</collision>
	</link>
	<link name="FR_thigh_rotor">
		<inertial>
			<origin rpy="0 0 0" xyz="0.0 0.0 0.0"></origin>
			<mass value="0.089"></mass>
			<inertia ixx="0.000059647" ixy="0.0" ixz="0.0" iyy="0.000111842" iyz="0.0" izz="0.000059647"></inertia>
		</inertial>
	</link>
	<link name="FR_calf">
		<inertial>
			<origin xyz="0.00548 0.000975 -0.115" rpy="0 0 0"></origin>
			<mass value="0.154"></mass>
			<inertia ixx="0.00108" ixy="-3.4E-07" ixz="1.72E-05" iyy="0.0011" iyz="-8.28E-06" izz="3.29E-05"></inertia>
		</inertial>
		<visual>
			<origin xyz="0 0 0" rpy="0 0 0"></origin>
			<geometry>
				<mesh filename="/home/chris/Desktop/go2/dae/calf_mirror.dae"></mesh>
			</geometry>
			<material name="">
				<color rgba="1 1 1 1"></color>
			</material>
		</visual>
		<collision>
			<geometry>
				<sphere radius="0.018131"></sphere>
			</geometry>
			<origin xyz="0.0005910000000000012 0.0 -0.013582999999999998" rpy="0 0 0"></origin>
		</collision>
		<collision>
			<geometry>
				<sphere radius="0.015623"></sphere>
			</geometry>
			<origin xyz="0.010321000000000002 -1e-06 -0.062791" rpy="0 0 0"></origin>
		</collision>
		<collision>
			<geometry>
				<sphere radius="0.015184"></sphere>
			</geometry>
			<origin xyz="0.017488000000000004 0.0 -0.09692200000000001" rpy="0 0 0"></origin>
		</collision>
		<collision>
			<geometry>
				<sphere radius="0.01571"></sphere>
			</geometry>
			<origin xyz="0.014173000000000002 0.0 -0.08058499999999999" rpy="0 0 0"></origin>
		</collision>
		<collision>
			<geometry>
				<sphere radius="0.018131"></sphere>
			</geometry>
			<origin xyz="0.019409000000000003 -1e-06 -0.106419" rpy="0 0 0"></origin>
		</collision>
		<collision>
			<geometry>
				<sphere radius="0.015246"></sphere>
			</geometry>
			<origin xyz="0.007164000000000002 0.0 -0.045919" rpy="0 0 0"></origin>
		</collision>
		<collision>
			<geometry>
				<sphere radius="0.015247"></sphere>
			</geometry>
			<origin xyz="0.003987000000000002 0.0 -0.030302" rpy="0 0 0"></origin>
		</collision>
		<collision>
			<geometry>
				<sphere radius="0.011306"></sphere>
			</geometry>
			<origin xyz="0.019153000000000003 0.005429 -0.111988" rpy="0 0 0"></origin>
		</collision>
	</link>
	<link name="FR_calflower">
		<collision>
			<geometry>
				<sphere radius="0.014132"></sphere>
			</geometry>
			<origin xyz="0.0 0.0 0.004524" rpy="0 0 0"></origin>
		</collision>
		<collision>
			<geometry>
				<sphere radius="0.01554"></sphere>
			</geometry>
			<origin xyz="0.0 0.0 -0.021523" rpy="0 0 0"></origin>
		</collision>
		<collision>
			<geometry>
				<sphere radius="0.013628"></sphere>
			</geometry>
			<origin xyz="-1e-06 0.0 -0.012392" rpy="0 0 0"></origin>
		</collision>
		<collision>
			<geometry>
				<sphere radius="0.015541"></sphere>
			</geometry>
			<origin xyz="0.0 0.0 0.021523" rpy="0 0 0"></origin>
		</collision>
	</link>
	<link name="FR_calflower1">
		<collision>
			<geometry>
				<sphere radius="0.02157"></sphere>
			</geometry>
			<origin xyz="0.0 1e-06 0.0" rpy="0 0 0"></origin>
		</collision>
	</link>
	<link name="FR_calf_rotor">
		<inertial>
			<origin rpy="0 0 0" xyz="0.0 0.0 0.0"></origin>
			<mass value="0.089"></mass>
			<inertia ixx="0.000059647" ixy="0.0" ixz="0.0" iyy="0.000111842" iyz="0.0" izz="0.000059647"></inertia>
		</inertial>
	</link>
	<link name="RL_hip">
		<inertial>
			<origin xyz="0.0054 0.00194 -0.000105" rpy="0 0 0"></origin>
			<mass value="0.678"></mass>
			<inertia ixx="0.00048" ixy="3.01E-06" ixz="-1.11E-06" iyy="0.000884" iyz="-1.42E-06" izz="0.000596"></inertia>
		</inertial>
		<visual>
			<origin xyz="0 0 0" rpy="0 3.1415 0"></origin>
			<geometry>
				<mesh filename="/home/chris/Desktop/go2/dae/hip.dae"></mesh>
			</geometry>
			<material name="">
				<color rgba="1 1 1 1"></color>
			</material>
		</visual>
		<collision>
			<geometry>
				<sphere radius="0.050163"></sphere>
			</geometry>
			<origin xyz="2e-06 0.080001 -2e-06" rpy="0 0 0"></origin>
		</collision>
	</link>
	<link name="RL_hip_rotor">
		<inertial>
			<origin rpy="0 0 0" xyz="0.0 0.0 0.0"></origin>
			<mass value="0.089"></mass>
			<inertia ixx="0.000111842" ixy="0.0" ixz="0.0" iyy="0.000059647" iyz="0.0" izz="0.000059647"></inertia>
		</inertial>
	</link>
	<link name="RL_thigh">
		<inertial>
			<origin xyz="-0.00374 -0.0223 -0.0327" rpy="0 0 0"></origin>
			<mass value="1.152"></mass>
			<inertia ixx="0.00584" ixy="8.72E-05" ixz="-0.000289" iyy="0.0058" iyz="0.000808" izz="0.00103"></inertia>
		</inertial>
		<visual>
			<origin xyz="0 0 0" rpy="0 0 0"></origin>
			<geometry>
				<mesh filename="/home/chris/Desktop/go2/dae/thigh.dae"></mesh>
			</geometry>
			<material name="">
				<color rgba="1 1 1 1"></color>
			</material>
		</visual>
		<collision>
			<geometry>
				<sphere radius="0.025579"></sphere>
			</geometry>
			<origin xyz="4.3e-05 0.0 -0.198381" rpy="0 0 0"></origin>
		</collision>
		<collision>
			<geometry>
				<sphere radius="0.024546"></sphere>
			</geometry>
			<origin xyz="-0.001662 0.0 -0.17118699999999998" rpy="0 0 0"></origin>
		</collision>
		<collision>
			<geometry>
				<sphere radius="0.025629"></sphere>
			</geometry>
			<origin xyz="0.001044 0.0 -0.142855" rpy="0 0 0"></origin>
		</collision>
		<collision>
			<geometry>
				<sphere radius="0.025191"></sphere>
			</geometry>
			<origin xyz="-0.001831 0.0 -0.113311" rpy="0 0 0"></origin>
		</collision>
		<collision>
			<geometry>
				<sphere radius="0.025179"></sphere>
			</geometry>
			<origin xyz="0.001768 0.0 -0.083894" rpy="0 0 0"></origin>
		</collision>
		<collision>
			<geometry>
				<sphere radius="0.025668"></sphere>
			</geometry>
			<origin xyz="-0.001052 0.0 -0.054338" rpy="0 0 0"></origin>
		</collision>
		<collision>
			<geometry>
				<sphere radius="0.023307"></sphere>
			</geometry>
			<origin xyz="5.7e-05 0.0 -0.028247999999999995" rpy="0 0 0"></origin>
		</collision>
		<collision>
			<geometry>
				<sphere radius="0.024271"></sphere>
			</geometry>
			<origin xyz="0.0 -1e-06 -0.012247999999999995" rpy="0 0 0"></origin>
		</collision>
	</link>
	<link name="RL_thigh_rotor">
		<inertial>
			<origin rpy="0 0 0" xyz="0.0 0.0 0.0"></origin>
			<mass value="0.089"></mass>
			<inertia ixx="0.000059647" ixy="0.0" ixz="0.0" iyy="0.000111842" iyz="0.0" izz="0.000059647"></inertia>
		</inertial>
	</link>
	<link name="RL_calf">
		<inertial>
			<origin xyz="0.00548 -0.000975 -0.115" rpy="0 0 0"></origin>
			<mass value="0.154"></mass>
			<inertia ixx="0.00108" ixy="3.4E-07" ixz="1.72E-05" iyy="0.0011" iyz="8.28E-06" izz="3.29E-05"></inertia>
		</inertial>
		<visual>
			<origin xyz="0 0 0" rpy="0 0 0"></origin>
			<geometry>
				<mesh filename="/home/chris/Desktop/go2/dae/calf.dae"></mesh>
			</geometry>
			<material name="">
				<color rgba="1 1 1 1"></color>
			</material>
		</visual>
		<collision>
			<geometry>
				<sphere radius="0.018131"></sphere>
			</geometry>
			<origin xyz="0.0005910000000000012 0.0 -0.013582999999999998" rpy="0 0 0"></origin>
		</collision>
		<collision>
			<geometry>
				<sphere radius="0.015623"></sphere>
			</geometry>
			<origin xyz="0.010321000000000002 -1e-06 -0.062791" rpy="0 0 0"></origin>
		</collision>
		<collision>
			<geometry>
				<sphere radius="0.015184"></sphere>
			</geometry>
			<origin xyz="0.017488000000000004 0.0 -0.09692200000000001" rpy="0 0 0"></origin>
		</collision>
		<collision>
			<geometry>
				<sphere radius="0.01571"></sphere>
			</geometry>
			<origin xyz="0.014173000000000002 0.0 -0.08058499999999999" rpy="0 0 0"></origin>
		</collision>
		<collision>
			<geometry>
				<sphere radius="0.018131"></sphere>
			</geometry>
			<origin xyz="0.019409000000000003 -1e-06 -0.106419" rpy="0 0 0"></origin>
		</collision>
		<collision>
			<geometry>
				<sphere radius="0.015246"></sphere>
			</geometry>
			<origin xyz="0.007164000000000002 0.0 -0.045919" rpy="0 0 0"></origin>
		</collision>
		<collision>
			<geometry>
				<sphere radius="0.015247"></sphere>
			</geometry>
			<origin xyz="0.003987000000000002 0.0 -0.030302" rpy="0 0 0"></origin>
		</collision>
		<collision>
			<geometry>
				<sphere radius="0.011306"></sphere>
			</geometry>
			<origin xyz="0.019153000000000003 0.005429 -0.111988" rpy="0 0 0"></origin>
		</collision>
	</link>
	<link name="RL_calflower">
		<collision>
			<geometry>
				<sphere radius="0.014132"></sphere>
			</geometry>
			<origin xyz="0.0 0.0 0.004524" rpy="0 0 0"></origin>
		</collision>
		<collision>
			<geometry>
				<sphere radius="0.01554"></sphere>
			</geometry>
			<origin xyz="0.0 0.0 -0.021523" rpy="0 0 0"></origin>
		</collision>
		<collision>
			<geometry>
				<sphere radius="0.013628"></sphere>
			</geometry>
			<origin xyz="-1e-06 0.0 -0.012392" rpy="0 0 0"></origin>
		</collision>
		<collision>
			<geometry>
				<sphere radius="0.015541"></sphere>
			</geometry>
			<origin xyz="0.0 0.0 0.021523" rpy="0 0 0"></origin>
		</collision>
	</link>
	<link name="RL_calflower1">
		<collision>
			<geometry>
				<sphere radius="0.02157"></sphere>
			</geometry>
			<origin xyz="0.0 1e-06 0.0" rpy="0 0 0"></origin>
		</collision>
	</link>
	<link name="RL_calf_rotor">
		<inertial>
			<origin rpy="0 0 0" xyz="0.0 0.0 0.0"></origin>
			<mass value="0.089"></mass>
			<inertia ixx="0.000059647" ixy="0.0" ixz="0.0" iyy="0.000111842" iyz="0.0" izz="0.000059647"></inertia>
		</inertial>
	</link>
	<link name="RR_hip">
		<inertial>
			<origin xyz="0.0054 -0.00194 -0.000105" rpy="0 0 0"></origin>
			<mass value="0.678"></mass>
			<inertia ixx="0.00048" ixy="-3.01E-06" ixz="-1.11E-06" iyy="0.000884" iyz="1.42E-06" izz="0.000596"></inertia>
		</inertial>
		<visual>
			<origin xyz="0 0 0" rpy="3.1415 3.1415 0"></origin>
			<geometry>
				<mesh filename="/home/chris/Desktop/go2/dae/hip.dae"></mesh>
			</geometry>
			<material name="">
				<color rgba="1 1 1 1"></color>
			</material>
		</visual>
		<collision>
			<geometry>
				<sphere radius="0.050163"></sphere>
			</geometry>
			<origin xyz="2e-06 -0.079999 -2e-06" rpy="0 0 0"></origin>
		</collision>
	</link>
	<link name="RR_hip_rotor">
		<inertial>
			<origin rpy="0 0 0" xyz="0.0 0.0 0.0"></origin>
			<mass value="0.089"></mass>
			<inertia ixx="0.000111842" ixy="0.0" ixz="0.0" iyy="0.000059647" iyz="0.0" izz="0.000059647"></inertia>
		</inertial>
	</link>
	<link name="RR_thigh">
		<inertial>
			<origin xyz="-0.00374 0.0223 -0.0327" rpy="0 0 0"></origin>
			<mass value="1.152"></mass>
			<inertia ixx="0.00584" ixy="-8.72E-05" ixz="-0.000289" iyy="0.0058" iyz="-0.000808" izz="0.00103"></inertia>
		</inertial>
		<visual>
			<origin xyz="0 0 0" rpy="0 0 0"></origin>
			<geometry>
				<mesh filename="/home/chris/Desktop/go2/dae/thigh_mirror.dae"></mesh>
			</geometry>
			<material name="">
				<color rgba="1 1 1 1"></color>
			</material>
		</visual>
		<collision>
			<geometry>
				<sphere radius="0.025579"></sphere>
			</geometry>
			<origin xyz="4.3e-05 0.0 -0.198381" rpy="0 0 0"></origin>
		</collision>
		<collision>
			<geometry>
				<sphere radius="0.024546"></sphere>
			</geometry>
			<origin xyz="-0.001662 0.0 -0.17118699999999998" rpy="0 0 0"></origin>
		</collision>
		<collision>
			<geometry>
				<sphere radius="0.025629"></sphere>
			</geometry>
			<origin xyz="0.001044 0.0 -0.142855" rpy="0 0 0"></origin>
		</collision>
		<collision>
			<geometry>
				<sphere radius="0.025191"></sphere>
			</geometry>
			<origin xyz="-0.001831 0.0 -0.113311" rpy="0 0 0"></origin>
		</collision>
		<collision>
			<geometry>
				<sphere radius="0.025179"></sphere>
			</geometry>
			<origin xyz="0.001768 0.0 -0.083894" rpy="0 0 0"></origin>
		</collision>
		<collision>
			<geometry>
				<sphere radius="0.025668"></sphere>
			</geometry>
			<origin xyz="-0.001052 0.0 -0.054338" rpy="0 0 0"></origin>
		</collision>
		<collision>
			<geometry>
				<sphere radius="0.023307"></sphere>
			</geometry>
			<origin xyz="5.7e-05 0.0 -0.028247999999999995" rpy="0 0 0"></origin>
		</collision>
		<collision>
			<geometry>
				<sphere radius="0.024271"></sphere>
			</geometry>
			<origin xyz="0.0 -1e-06 -0.012247999999999995" rpy="0 0 0"></origin>
		</collision>
	</link>
	<link name="RR_thigh_rotor">
		<inertial>
			<origin rpy="0 0 0" xyz="0.0 0.0 0.0"></origin>
			<mass value="0.089"></mass>
			<inertia ixx="0.000059647" ixy="0.0" ixz="0.0" iyy="0.000111842" iyz="0.0" izz="0.000059647"></inertia>
		</inertial>
	</link>
	<link name="RR_calf">
		<inertial>
			<origin xyz="0.00548 0.000975 -0.115" rpy="0 0 0"></origin>
			<mass value="0.154"></mass>
			<inertia ixx="0.00108" ixy="-3.4E-07" ixz="1.72E-05" iyy="0.0011" iyz="-8.28E-06" izz="3.29E-05"></inertia>
		</inertial>
		<visual>
			<origin xyz="0 0 0" rpy="0 0 0"></origin>
			<geometry>
				<mesh filename="/home/chris/Desktop/go2/dae/calf_mirror.dae"></mesh>
			</geometry>
			<material name="">
				<color rgba="1 1 1 1"></color>
			</material>
		</visual>
		<collision>
			<geometry>
				<sphere radius="0.018131"></sphere>
			</geometry>
			<origin xyz="0.0005910000000000012 0.0 -0.013582999999999998" rpy="0 0 0"></origin>
		</collision>
		<collision>
			<geometry>
				<sphere radius="0.015623"></sphere>
			</geometry>
			<origin xyz="0.010321000000000002 -1e-06 -0.062791" rpy="0 0 0"></origin>
		</collision>
		<collision>
			<geometry>
				<sphere radius="0.015184"></sphere>
			</geometry>
			<origin xyz="0.017488000000000004 0.0 -0.09692200000000001" rpy="0 0 0"></origin>
		</collision>
		<collision>
			<geometry>
				<sphere radius="0.01571"></sphere>
			</geometry>
			<origin xyz="0.014173000000000002 0.0 -0.08058499999999999" rpy="0 0 0"></origin>
		</collision>
		<collision>
			<geometry>
				<sphere radius="0.018131"></sphere>
			</geometry>
			<origin xyz="0.019409000000000003 -1e-06 -0.106419" rpy="0 0 0"></origin>
		</collision>
		<collision>
			<geometry>
				<sphere radius="0.015246"></sphere>
			</geometry>
			<origin xyz="0.007164000000000002 0.0 -0.045919" rpy="0 0 0"></origin>
		</collision>
		<collision>
			<geometry>
				<sphere radius="0.015247"></sphere>
			</geometry>
			<origin xyz="0.003987000000000002 0.0 -0.030302" rpy="0 0 0"></origin>
		</collision>
		<collision>
			<geometry>
				<sphere radius="0.011306"></sphere>
			</geometry>
			<origin xyz="0.019153000000000003 0.005429 -0.111988" rpy="0 0 0"></origin>
		</collision>
	</link>
	<link name="RR_calflower">
		<collision>
			<geometry>
				<sphere radius="0.014132"></sphere>
			</geometry>
			<origin xyz="0.0 0.0 0.004524" rpy="0 0 0"></origin>
		</collision>
		<collision>
			<geometry>
				<sphere radius="0.01554"></sphere>
			</geometry>
			<origin xyz="0.0 0.0 -0.021523" rpy="0 0 0"></origin>
		</collision>
		<collision>
			<geometry>
				<sphere radius="0.013628"></sphere>
			</geometry>
			<origin xyz="-1e-06 0.0 -0.012392" rpy="0 0 0"></origin>
		</collision>
		<collision>
			<geometry>
				<sphere radius="0.015541"></sphere>
			</geometry>
			<origin xyz="0.0 0.0 0.021523" rpy="0 0 0"></origin>
		</collision>
	</link>
	<link name="RR_calflower1">
		<collision>
			<geometry>
				<sphere radius="0.02157"></sphere>
			</geometry>
			<origin xyz="0.0 1e-06 0.0" rpy="0 0 0"></origin>
		</collision>
	</link>
	<link name="RR_calf_rotor">
		<inertial>
			<origin rpy="0 0 0" xyz="0.0 0.0 0.0"></origin>
			<mass value="0.089"></mass>
			<inertia ixx="0.000059647" ixy="0.0" ixz="0.0" iyy="0.000111842" iyz="0.0" izz="0.000059647"></inertia>
		</inertial>
	</link>
	<joint name="Head_upper_joint" type="fixed" dont_collapse="true">
		<origin xyz="0.285 0 0.01" rpy="0 0 0"></origin>
		<parent link="base"></parent>
		<child link="Head_upper"></child>
		<axis xyz="0 0 0"></axis>
	</joint>
	<joint name="FL_hip_joint" type="revolute">
		<origin xyz="0.1934 0.0465 0" rpy="0 0 0"></origin>
		<parent link="base"></parent>
		<child link="FL_hip"></child>
		<axis xyz="1 0 0"></axis>
		<limit lower="-1.0472" upper="1.0472" effort="23.7" velocity="30.1"></limit>
	</joint>
	<joint name="FL_hip_rotor_joint" type="fixed">
		<origin rpy="0 0 0" xyz="0.11215 0.04675 0"></origin>
		<parent link="base"></parent>
		<child link="FL_hip_rotor"></child>
	</joint>
	<joint name="FL_thigh_joint" type="revolute">
		<origin xyz="0 0.0955 0" rpy="0 0 0"></origin>
		<parent link="FL_hip"></parent>
		<child link="FL_thigh"></child>
		<axis xyz="0 1 0"></axis>
		<limit lower="-1.5708" upper="3.4907" effort="23.7" velocity="30.1"></limit>
	</joint>
	<joint name="FL_thigh_rotor_joint" type="fixed">
		<origin rpy="0 0 0" xyz="0 -0.00015 0"></origin>
		<parent link="FL_hip"></parent>
		<child link="FL_thigh_rotor"></child>
	</joint>
	<joint name="FL_calf_joint" type="revolute">
		<origin xyz="0 0 -0.213" rpy="0 0 0"></origin>
		<parent link="FL_thigh"></parent>
		<child link="FL_calf"></child>
		<axis xyz="0 1 0"></axis>
		<limit lower="-2.7227" upper="-0.83776" effort="45.43" velocity="15.70"></limit>
	</joint>
	<joint name="FL_calflower_joint" type="fixed">
		<origin xyz="0.020 0 -0.148" rpy="0 0.05 0"></origin>
		<parent link="FL_calf"></parent>
		<child link="FL_calflower"></child>
		<axis xyz="0 0 0"></axis>
	</joint>
	<joint name="FL_calflower1_joint" type="fixed">
		<origin xyz="-0.01 0 -0.04" rpy="0 0.48 0"></origin>
		<parent link="FL_calflower"></parent>
		<child link="FL_calflower1"></child>
		<axis xyz="0 0 0"></axis>
	</joint>
	<joint name="FL_calf_rotor_joint" type="fixed">
		<origin rpy="0 0 0" xyz="0 -0.03235 0"></origin>
		<parent link="FL_thigh"></parent>
		<child link="FL_calf_rotor"></child>
	</joint>
	<joint name="FR_hip_joint" type="revolute">
		<origin xyz="0.1934 -0.0465 0" rpy="0 0 0"></origin>
		<parent link="base"></parent>
		<child link="FR_hip"></child>
		<axis xyz="1 0 0"></axis>
		<limit lower="-1.0472" upper="1.0472" effort="23.7" velocity="30.1"></limit>
	</joint>
	<joint name="FR_hip_rotor_joint" type="fixed">
		<origin rpy="0 0 0" xyz="0.11215 -0.04675 0"></origin>
		<parent link="base"></parent>
		<child link="FR_hip_rotor"></child>
	</joint>
	<joint name="FR_thigh_joint" type="revolute">
		<origin xyz="0 -0.0955 0" rpy="0 0 0"></origin>
		<parent link="FR_hip"></parent>
		<child link="FR_thigh"></child>
		<axis xyz="0 1 0"></axis>
		<limit lower="-1.5708" upper="3.4907" effort="23.7" velocity="30.1"></limit>
	</joint>
	<joint name="FR_thigh_rotor_joint" type="fixed">
		<origin rpy="0 0 0" xyz="0 0.00015 0"></origin>
		<parent link="FR_hip"></parent>
		<child link="FR_thigh_rotor"></child>
	</joint>
	<joint name="FR_calf_joint" type="revolute">
		<origin xyz="0 0 -0.213" rpy="0 0 0"></origin>
		<parent link="FR_thigh"></parent>
		<child link="FR_calf"></child>
		<axis xyz="0 1 0"></axis>
		<limit lower="-2.7227" upper="-0.83776" effort="45.43" velocity="15.70"></limit>
	</joint>
	<joint name="FR_calflower_joint" type="fixed">
		<origin xyz="0.020 0 -0.148" rpy="0 0.05 0"></origin>
		<parent link="FR_calf"></parent>
		<child link="FR_calflower"></child>
		<axis xyz="0 0 0"></axis>
	</joint>
	<joint name="FR_calflower1_joint" type="fixed">
		<origin xyz="-0.01 0 -0.04" rpy="0 0.48 0"></origin>
		<parent link="FR_calflower"></parent>
		<child link="FR_calflower1"></child>
		<axis xyz="0 0 0"></axis>
	</joint>
	<joint name="FR_calf_rotor_joint" type="fixed">
		<origin rpy="0 0 0" xyz="0 0.03235 0"></origin>
		<parent link="FR_thigh"></parent>
		<child link="FR_calf_rotor"></child>
	</joint>
	<joint name="RL_hip_joint" type="revolute">
		<origin xyz="-0.1934 0.0465 0" rpy="0 0 0"></origin>
		<parent link="base"></parent>
		<child link="RL_hip"></child>
		<axis xyz="1 0 0"></axis>
		<limit lower="-1.0472" upper="1.0472" effort="23.7" velocity="30.1"></limit>
	</joint>
	<joint name="RL_hip_rotor_joint" type="fixed">
		<origin rpy="0 0 0" xyz="-0.11215 0.04675 0"></origin>
		<parent link="base"></parent>
		<child link="RL_hip_rotor"></child>
	</joint>
	<joint name="RL_thigh_joint" type="revolute">
		<origin xyz="0 0.0955 0" rpy="0 0 0"></origin>
		<parent link="RL_hip"></parent>
		<child link="RL_thigh"></child>
		<axis xyz="0 1 0"></axis>
		<limit lower="-0.5236" upper="4.5379" effort="23.7" velocity="30.1"></limit>
	</joint>
	<joint name="RL_thigh_rotor_joint" type="fixed">
		<origin rpy="0 0 0" xyz="0 -0.00015 0"></origin>
		<parent link="RL_hip"></parent>
		<child link="RL_thigh_rotor"></child>
	</joint>
	<joint name="RL_calf_joint" type="revolute">
		<origin xyz="0 0 -0.213" rpy="0 0 0"></origin>
		<parent link="RL_thigh"></parent>
		<child link="RL_calf"></child>
		<axis xyz="0 1 0"></axis>
		<limit lower="-2.7227" upper="-0.83776" effort="45.43" velocity="15.70"></limit>
	</joint>
	<joint name="RL_calflower_joint" type="fixed">
		<origin xyz="0.020 0 -0.148" rpy="0 0.05 0"></origin>
		<parent link="RL_calf"></parent>
		<child link="RL_calflower"></child>
		<axis xyz="0 0 0"></axis>
	</joint>
	<joint name="RL_calflower1_joint" type="fixed">
		<origin xyz="-0.01 0 -0.04" rpy="0 0.48 0"></origin>
		<parent link="RL_calflower"></parent>
		<child link="RL_calflower1"></child>
		<axis xyz="0 0 0"></axis>
	</joint>
	<joint name="RL_calf_rotor_joint" type="fixed">
		<origin rpy="0 0 0" xyz="0 -0.03235 0"></origin>
		<parent link="RL_thigh"></parent>
		<child link="RL_calf_rotor"></child>
	</joint>
	<joint name="RR_hip_joint" type="revolute">
		<origin xyz="-0.1934 -0.0465 0" rpy="0 0 0"></origin>
		<parent link="base"></parent>
		<child link="RR_hip"></child>
		<axis xyz="1 0 0"></axis>
		<limit lower="-1.0472" upper="1.0472" effort="23.7" velocity="30.1"></limit>
	</joint>
	<joint name="RR_hip_rotor_joint" type="fixed">
		<origin rpy="0 0 0" xyz="-0.11215 -0.04675 0"></origin>
		<parent link="base"></parent>
		<child link="RR_hip_rotor"></child>
	</joint>
	<joint name="RR_thigh_joint" type="revolute">
		<origin xyz="0 -0.0955 0" rpy="0 0 0"></origin>
		<parent link="RR_hip"></parent>
		<child link="RR_thigh"></child>
		<axis xyz="0 1 0"></axis>
		<limit lower="-0.5236" upper="4.5379" effort="23.7" velocity="30.1"></limit>
	</joint>
	<joint name="RR_thigh_rotor_joint" type="fixed">
		<origin rpy="0 0 0" xyz="0 0.00015 0"></origin>
		<parent link="RR_hip"></parent>
		<child link="RR_thigh_rotor"></child>
	</joint>
	<joint name="RR_calf_joint" type="revolute">
		<origin xyz="0 0 -0.213" rpy="0 0 0"></origin>
		<parent link="RR_thigh"></parent>
		<child link="RR_calf"></child>
		<axis xyz="0 1 0"></axis>
		<limit lower="-2.7227" upper="-0.83776" effort="45.43" velocity="15.70"></limit>
	</joint>
	<joint name="RR_calflower_joint" type="fixed">
		<origin xyz="0.020 0 -0.148" rpy="0 0.05 0"></origin>
		<parent link="RR_calf"></parent>
		<child link="RR_calflower"></child>
		<axis xyz="0 0 0"></axis>
	</joint>
	<joint name="RR_calflower1_joint" type="fixed">
		<origin xyz="-0.01 0 -0.04" rpy="0 0.48 0"></origin>
		<parent link="RR_calflower"></parent>
		<child link="RR_calflower1"></child>
		<axis xyz="0 0 0"></axis>
	</joint>
	<joint name="RR_calf_rotor_joint" type="fixed">
		<origin rpy="0 0 0" xyz="0 0.03235 0"></origin>
		<parent link="RR_thigh"></parent>
		<child link="RR_calf_rotor"></child>
	</joint>
</robot>