<?xml version="1.0" encoding="utf-8"?>
<robot name="b1_description" path="/home/chris/Desktop/awesome-loco-manipulation/robots/B1_Z1/urdf/z1.urdf">
	<material name="black">
		<color rgba="0.0 0.0 0.0 1.0"></color>
	</material>
	<material name="blue">
		<color rgba="0.0 0.0 0.8 1.0"></color>
	</material>
	<material name="green">
		<color rgba="0.0 0.8 0.0 1.0"></color>
	</material>
	<material name="grey">
		<color rgba="0.2 0.2 0.2 1.0"></color>
	</material>
	<material name="silver">
		<color rgba="0.9137254901960784 0.9137254901960784 0.8470588235294118 1.0"></color>
	</material>
	<material name="orange">
		<color rgba="1.0 0.4235294117647059 0.0392156862745098 1.0"></color>
	</material>
	<material name="brown">
		<color rgba="0.8705882352941177 0.8117647058823529 0.7647058823529411 1.0"></color>
	</material>
	<material name="red">
		<color rgba="0.8 0.0 0.0 1.0"></color>
	</material>
	<material name="white">
		<color rgba="1.0 1.0 1.0 1.0"></color>
	</material>
	<joint name="trunk_arm_joint0" type="fixed" dont_collapse="true">
		<origin rpy="0 0 0" xyz="0.2535 0 0.056"></origin>
		<parent link="trunk"></parent>
		<child link="arm_link00"></child>
	</joint>
	<joint name="arm_joint1" type="revolute">
		<origin rpy="0 0 0" xyz="0 0 0.0585"></origin>
		<parent link="arm_link00"></parent>
		<child link="arm_link01"></child>
		<axis xyz="0 0 1"></axis>
		<dynamics damping="1.0" friction="1.0"></dynamics>
		<limit effort="30.0" lower="-2.6179938779914944" upper="2.6179938779914944" velocity="3.1415"></limit>
	</joint>
	<joint name="arm_joint2" type="revolute">
		<origin rpy="0 0 0" xyz="0 0 0.045"></origin>
		<parent link="arm_link01"></parent>
		<child link="arm_link02"></child>
		<axis xyz="0 1 0"></axis>
		<dynamics damping="2.0" friction="2.0"></dynamics>
		<limit effort="60.0" lower="0.0" upper="2.9670597283903604" velocity="3.1415"></limit>
	</joint>
	<joint name="arm_joint3" type="revolute">
		<origin rpy="0 0 0" xyz="-0.35 0 0"></origin>
		<parent link="arm_link02"></parent>
		<child link="arm_link03"></child>
		<axis xyz="0 1 0"></axis>
		<dynamics damping="1.0" friction="1.0"></dynamics>
		<limit effort="30.0" lower="-2.8797932657906435" upper="0.0" velocity="3.1415"></limit>
	</joint>
	<joint name="arm_joint4" type="revolute">
		<origin rpy="0 0 0" xyz="0.218 0 0.057"></origin>
		<parent link="arm_link03"></parent>
		<child link="arm_link04"></child>
		<axis xyz="0 1 0"></axis>
		<dynamics damping="1.0" friction="1.0"></dynamics>
		<limit effort="30.0" lower="-1.5184364492350666" upper="1.5184364492350666" velocity="3.1415"></limit>
	</joint>
	<joint name="arm_joint5" type="revolute">
		<origin rpy="0 0 0" xyz="0.07 0.0 0.0"></origin>
		<parent link="arm_link04"></parent>
		<child link="arm_link05"></child>
		<axis xyz="0 0 1"></axis>
		<dynamics damping="1.0" friction="1.0"></dynamics>
		<limit effort="30.0" lower="-1.3439035240356338" upper="1.3439035240356338" velocity="3.1415"></limit>
	</joint>
	<joint name="arm_joint6" type="revolute">
		<origin rpy="0 0 0" xyz="0.0492 0.0 0.0"></origin>
		<parent link="arm_link05"></parent>
		<child link="arm_link06"></child>
		<axis xyz="1 0 0"></axis>
		<dynamics damping="1.0" friction="1.0"></dynamics>
		<limit effort="30.0" lower="-2.792526803190927" upper="2.792526803190927" velocity="3.1415"></limit>
	</joint>
	<joint name="gripperStator" type="fixed">
		<origin rpy="0 0 0" xyz="0.051 0.0 0.0"></origin>
		<parent link="arm_link06"></parent>
		<child link="gripperStator"></child>
	</joint>
	<joint name="jointGripper" type="revolute">
		<origin rpy="0 0 0" xyz="0.049 0.0 0"></origin>
		<parent link="gripperStator"></parent>
		<child link="gripperMover"></child>
		<axis xyz="0 1 0"></axis>
		<dynamics damping="1.0" friction="1.0"></dynamics>
		<limit effort="30.0" lower="-1.5707963267948966" upper="0.0" velocity="3.1415"></limit>
	</joint>
	<joint name="floating_base" type="fixed">
		<origin rpy="0 0 0" xyz="0 0 0"></origin>
		<parent link="base"></parent>
		<child link="trunk"></child>
	</joint>
	<link name="arm_link00">
		<visual>
			<origin rpy="0 0 0" xyz="0 0 0"></origin>
			<geometry>
				<mesh filename="/home/chris/Desktop/awesome-loco-manipulation/robots/B1_Z1/meshes/z1_Link00.dae" scale="1 1 1"></mesh>
			</geometry>
		</visual>
		<collision>
			<geometry>
				<sphere radius="0.060756"></sphere>
			</geometry>
			<origin xyz="8.940696718130053e-11 -1e-06 0.05475099967217445" rpy="0 0 0"></origin>
		</collision>
		<collision>
			<geometry>
				<sphere radius="0.055034"></sphere>
			</geometry>
			<origin xyz="-0.031161999910593034 1e-06 0.04933699967217445" rpy="0 0 0"></origin>
		</collision>
		<inertial>
			<origin rpy="0 0 0" xyz="-0.00334984 -0.00013615 0.02495843"></origin>
			<mass value="0.47247481"></mass>
			<inertia ixx="0.00037937" ixy="-3.5e-07" ixz="-1.037e-05" iyy="0.00041521" iyz="-9.9e-07" izz="0.00053066"></inertia>
		</inertial>
	</link>
	<link name="arm_link01">
		<visual>
			<origin rpy="0 0 0" xyz="0 0 0"></origin>
			<geometry>
				<mesh filename="/home/chris/Desktop/awesome-loco-manipulation/robots/B1_Z1/meshes/z1_Link01.dae" scale="1 1 1"></mesh>
			</geometry>
		</visual>
		<collision>
			<geometry>
				<sphere radius="0.026468"></sphere>
			</geometry>
			<origin xyz="0.001245180542702948 0.05857623062629675 0.04297709231208779" rpy="0 0 0"></origin>
		</collision>
		<collision>
			<geometry>
				<sphere radius="0.03201"></sphere>
			</geometry>
			<origin xyz="0.000771180542702948 -0.05854476937370325 0.03695509231208779" rpy="0 0 0"></origin>
		</collision>
		<collision>
			<geometry>
				<sphere radius="0.029043"></sphere>
			</geometry>
			<origin xyz="-0.019704819457297053 -0.03430376937370325 0.009923092312087791" rpy="0 0 0"></origin>
		</collision>
		<collision>
			<geometry>
				<sphere radius="0.028721"></sphere>
			</geometry>
			<origin xyz="0.020045180542702948 -0.03820476937370325 0.012227092312087788" rpy="0 0 0"></origin>
		</collision>
		<collision>
			<geometry>
				<sphere radius="0.026574"></sphere>
			</geometry>
			<origin xyz="0.018923180542702946 -0.0003967693737032498 0.004492092312087789" rpy="0 0 0"></origin>
		</collision>
		<collision>
			<geometry>
				<sphere radius="0.030081"></sphere>
			</geometry>
			<origin xyz="-0.025018819457297052 0.01336223062629675 0.0061980923120877884" rpy="0 0 0"></origin>
		</collision>
		<collision>
			<geometry>
				<sphere radius="0.026709"></sphere>
			</geometry>
			<origin xyz="-0.012633819457297052 0.04968823062629675 0.01588109231208779" rpy="0 0 0"></origin>
		</collision>
		<collision>
			<geometry>
				<sphere radius="0.028348"></sphere>
			</geometry>
			<origin xyz="0.02118718054270295 0.03806023062629675 0.01324509231208779" rpy="0 0 0"></origin>
		</collision>
		<inertial>
			<origin rpy="0 0 0" xyz="2.47e-06 -0.00025198 0.02317169"></origin>
			<mass value="0.67332551"></mass>
			<inertia ixx="0.00128328" ixy="-6e-08" ixz="-4e-07" iyy="0.00071931" iyz="5e-07" izz="0.00083936"></inertia>
		</inertial>
	</link>
	<link name="arm_link02">
		<visual>
			<origin rpy="0 0 0" xyz="0 0 0"></origin>
			<geometry>
				<mesh filename="/home/chris/Desktop/awesome-loco-manipulation/robots/B1_Z1/meshes/z1_Link02.dae" scale="1 1 1"></mesh>
			</geometry>
		</visual>
		<collision>
			<geometry>
				<sphere radius="0.052938"></sphere>
			</geometry>
			<origin xyz="-0.00673130895907148 -0.02094682708254493 -1.9380044090946464e-05" rpy="0 0 0"></origin>
		</collision>
		<collision>
			<geometry>
				<sphere radius="0.054902"></sphere>
			</geometry>
			<origin xyz="-0.006401308959071483 0.02152217291745507 0.00041261995590905355" rpy="0 0 0"></origin>
		</collision>
		<collision>
			<geometry>
				<sphere radius="0.051429"></sphere>
			</geometry>
			<origin xyz="-0.0833633089590715 -0.00079382708254493 -0.0014293800440909464" rpy="0 0 0"></origin>
		</collision>
		<collision>
			<geometry>
				<sphere radius="0.049923"></sphere>
			</geometry>
			<origin xyz="-0.1638383089590715 -0.00055282708254493 5.961995590905354e-05" rpy="0 0 0"></origin>
		</collision>
		<collision>
			<geometry>
				<sphere radius="0.048051"></sphere>
			</geometry>
			<origin xyz="-0.2405523089590715 0.00234417291745507 -0.00031838004409094644" rpy="0 0 0"></origin>
		</collision>
		<collision>
			<geometry>
				<sphere radius="0.044017"></sphere>
			</geometry>
			<origin xyz="-0.3037263089590715 0.01467517291745507 -0.0027733800440909464" rpy="0 0 0"></origin>
		</collision>
		<collision>
			<geometry>
				<sphere radius="0.036535"></sphere>
			</geometry>
			<origin xyz="-0.3512523089590715 0.02734117291745507 0.015934619955909054" rpy="0 0 0"></origin>
		</collision>
		<collision>
			<geometry>
				<sphere radius="0.036406"></sphere>
			</geometry>
			<origin xyz="-0.3547313089590715 0.02816917291745507 -0.012438380044090947" rpy="0 0 0"></origin>
		</collision>
		<inertial>
			<origin rpy="0 0 0" xyz="-0.11012601 0.00240029 0.00158266"></origin>
			<mass value="1.19132258"></mass>
			<inertia ixx="0.00102138" ixy="0.00062358" ixz="5.13e-06" iyy="0.02429457" iyz="-2.1e-06" izz="0.02466114"></inertia>
		</inertial>
	</link>
	<link name="arm_link03">
		<visual>
			<origin rpy="0 0 0" xyz="0 0 0"></origin>
			<geometry>
				<mesh filename="/home/chris/Desktop/awesome-loco-manipulation/robots/B1_Z1/meshes/z1_Link03.dae" scale="1 1 1"></mesh>
			</geometry>
		</visual>
		<collision>
			<geometry>
				<sphere radius="0.048094"></sphere>
			</geometry>
			<origin xyz="0.12769734966570093 -0.007983309988955621 0.05555365031257606" rpy="0 0 0"></origin>
		</collision>
		<collision>
			<geometry>
				<sphere radius="0.046621"></sphere>
			</geometry>
			<origin xyz="0.18521834966570094 -0.006460309988955622 -0.16343134968742395" rpy="0 0 0"></origin>
		</collision>
		<collision>
			<geometry>
				<sphere radius="0.040308"></sphere>
			</geometry>
			<origin xyz="0.18556734966570093 -0.0017753099889556223 -0.12465834968742394" rpy="0 0 0"></origin>
		</collision>
		<collision>
			<geometry>
				<sphere radius="0.037799"></sphere>
			</geometry>
			<origin xyz="0.18504034966570093 -0.00020230998895562173 -0.07060034968742393" rpy="0 0 0"></origin>
		</collision>
		<collision>
			<geometry>
				<sphere radius="0.035041"></sphere>
			</geometry>
			<origin xyz="0.18396534966570094 -0.0018023099889556225 -0.020669349687423934" rpy="0 0 0"></origin>
		</collision>
		<collision>
			<geometry>
				<sphere radius="0.032801"></sphere>
			</geometry>
			<origin xyz="0.17429534966570093 -0.009939309988955623 0.01065065031257606" rpy="0 0 0"></origin>
		</collision>
		<collision>
			<geometry>
				<sphere radius="0.037784"></sphere>
			</geometry>
			<origin xyz="0.15470834966570093 -0.013318309988955623 0.03853965031257606" rpy="0 0 0"></origin>
		</collision>
		<collision>
			<geometry>
				<sphere radius="0.03498"></sphere>
			</geometry>
			<origin xyz="0.15369434966570095 -0.013971309988955622 0.024586650312576064" rpy="0 0 0"></origin>
		</collision>
		<inertial>
			<origin rpy="0 0 0" xyz="0.10609208 -0.00541815 0.03476383"></origin>
			<mass value="0.83940874"></mass>
			<inertia ixx="0.00108061" ixy="-8.669e-05" ixz="-0.00208102" iyy="0.00954238" iyz="-1.332e-05" izz="0.00886621"></inertia>
		</inertial>
	</link>
	<link name="arm_link04">
		<visual>
			<origin rpy="0 0 0" xyz="0 0 0"></origin>
			<geometry>
				<mesh filename="/home/chris/Desktop/awesome-loco-manipulation/robots/B1_Z1/meshes/z1_Link04.dae" scale="1 1 1"></mesh>
			</geometry>
		</visual>
		<collision>
			<geometry>
				<sphere radius="0.049002"></sphere>
			</geometry>
			<origin xyz="0.13840104177200793 0.0014234001110792162 -0.007795058233737945" rpy="0 0 0"></origin>
		</collision>
		<collision>
			<geometry>
				<sphere radius="0.029367"></sphere>
			</geometry>
			<origin xyz="0.08849004177200795 0.027526400111079215 -0.0029790582337379454" rpy="0 0 0"></origin>
		</collision>
		<collision>
			<geometry>
				<sphere radius="0.028533"></sphere>
			</geometry>
			<origin xyz="0.06627804177200794 0.030407400111079216 0.014832941766262056" rpy="0 0 0"></origin>
		</collision>
		<collision>
			<geometry>
				<sphere radius="0.02845"></sphere>
			</geometry>
			<origin xyz="0.06131404177200794 0.030405400111079214 -0.011799058233737945" rpy="0 0 0"></origin>
		</collision>
		<inertial>
			<origin rpy="0 0 0" xyz="0.04366681 0.00364738 -0.00170192"></origin>
			<mass value="0.56404563"></mass>
			<inertia ixx="0.00031576" ixy="8.13e-05" ixz="4.091e-05" iyy="0.00092996" iyz="-5.96e-06" izz="0.00097912"></inertia>
		</inertial>
	</link>
	<link name="arm_link05">
		<visual>
			<origin rpy="0 0 0" xyz="0 0 0"></origin>
			<geometry>
				<mesh filename="/home/chris/Desktop/awesome-loco-manipulation/robots/B1_Z1/meshes/z1_Link05.dae" scale="1 1 1"></mesh>
			</geometry>
		</visual>
		<collision>
			<geometry>
				<sphere radius="0.033854"></sphere>
			</geometry>
			<origin xyz="0.002181286601066589 -0.000515 0.030149001341104507" rpy="0 0 0"></origin>
		</collision>
		<collision>
			<geometry>
				<sphere radius="0.033933"></sphere>
			</geometry>
			<origin xyz="0.03871028660106659 0.000401 -0.0008969986588954924" rpy="0 0 0"></origin>
		</collision>
		<collision>
			<geometry>
				<sphere radius="0.029735"></sphere>
			</geometry>
			<origin xyz="0.02850228660106659 0.017122 0.023790001341104507" rpy="0 0 0"></origin>
		</collision>
		<collision>
			<geometry>
				<sphere radius="0.032373"></sphere>
			</geometry>
			<origin xyz="0.03885928660106659 -0.017802 0.012736001341104508" rpy="0 0 0"></origin>
		</collision>
		<inertial>
			<origin rpy="0 0 0" xyz="0.03121533 0.0 0.00646316"></origin>
			<mass value="0.38938492"></mass>
			<inertia ixx="0.00017605" ixy="4e-07" ixz="5.689e-05" iyy="0.00055896" iyz="-1.3e-07" izz="0.0005386"></inertia>
		</inertial>
	</link>
	<link name="arm_link06">
		<visual>
			<origin rpy="0 0 0" xyz="0 0 0"></origin>
			<geometry>
				<mesh filename="/home/chris/Desktop/awesome-loco-manipulation/robots/B1_Z1/meshes/z1_Link06.dae" scale="1 1 1"></mesh>
			</geometry>
		</visual>
		<collision>
			<geometry>
				<sphere radius="0.040859"></sphere>
			</geometry>
			<origin xyz="0.025498999999999994 2e-06 -0.024759999516038224" rpy="0 0 0"></origin>
		</collision>
		<inertial>
			<origin rpy="0 0 0" xyz="0.0241569 -0.00017355 -0.00143876"></origin>
			<mass value="0.28875807"></mass>
			<inertia ixx="0.00018328" ixy="1.22e-06" ixz="5.4e-07" iyy="0.0001475" iyz="8e-08" izz="0.0001468"></inertia>
		</inertial>
	</link>
	<link name="gripperStator">
		<visual>
			<geometry>
				<mesh filename="/home/chris/Desktop/awesome-loco-manipulation/robots/B1_Z1/meshes/z1_GripperStator.dae" scale="1 1 1"></mesh>
			</geometry>
		</visual>
		<collision>
			<geometry>
				<sphere radius="0.056715"></sphere>
			</geometry>
			<origin xyz="0.038118372240885635 0.0009816293523981176 0.00018430395172673412" rpy="0 0 0"></origin>
		</collision>
		<collision>
			<geometry>
				<sphere radius="0.040101"></sphere>
			</geometry>
			<origin xyz="0.07820037224088563 0.020740629352398118 -0.019082696048273267" rpy="0 0 0"></origin>
		</collision>
		<collision>
			<geometry>
				<sphere radius="0.039912"></sphere>
			</geometry>
			<origin xyz="0.07660737224088564 -0.02239737064760188 -0.019081696048273266" rpy="0 0 0"></origin>
		</collision>
		<collision>
			<geometry>
				<sphere radius="0.035042"></sphere>
			</geometry>
			<origin xyz="0.12619237224088564 -0.01966337064760188 -0.021274696048273267" rpy="0 0 0"></origin>
		</collision>
		<collision>
			<geometry>
				<sphere radius="0.03501"></sphere>
			</geometry>
			<origin xyz="0.12745837224088563 0.017132629352398118 -0.021041696048273266" rpy="0 0 0"></origin>
		</collision>
		<inertial>
			<origin rpy="0 0 0" xyz="0.04764427 -0.00035819 -0.00249162"></origin>
			<mass value="0.52603655"></mass>
			<inertia ixx="0.00038683" ixy="-3.59e-06" ixz="7.662e-05" iyy="0.00068614" iyz="2.09e-06" izz="0.00066293"></inertia>
		</inertial>
	</link>
	<link name="gripperMover">
		<visual>
			<geometry>
				<mesh filename="/home/chris/Desktop/awesome-loco-manipulation/robots/B1_Z1/meshes/z1_GripperMover.dae" scale="1 1 1"></mesh>
			</geometry>
		</visual>
		<collision>
			<geometry>
				<sphere radius="0.028601"></sphere>
			</geometry>
			<origin xyz="0.0013451956993122752 0.03513618772499222 0.004130578851448419" rpy="0 0 0"></origin>
		</collision>
		<collision>
			<geometry>
				<sphere radius="0.032393"></sphere>
			</geometry>
			<origin xyz="0.04020319569931228 0.024170187724992215 0.013287578851448418" rpy="0 0 0"></origin>
		</collision>
		<collision>
			<geometry>
				<sphere radius="0.034005"></sphere>
			</geometry>
			<origin xyz="0.07491019569931227 0.013441187724992214 0.004091578851448419" rpy="0 0 0"></origin>
		</collision>
		<collision>
			<geometry>
				<sphere radius="0.033737"></sphere>
			</geometry>
			<origin xyz="0.07304119569931228 -0.015425812275007786 0.004931578851448419" rpy="0 0 0"></origin>
		</collision>
		<collision>
			<geometry>
				<sphere radius="0.031067"></sphere>
			</geometry>
			<origin xyz="0.03748919569931228 -0.028555812275007787 0.01264857885144842" rpy="0 0 0"></origin>
		</collision>
		<collision>
			<geometry>
				<sphere radius="0.027721"></sphere>
			</geometry>
			<origin xyz="0.00036919569931227747 -0.03580681227500779 0.0037405788514484188" rpy="0 0 0"></origin>
		</collision>
		<inertial>
			<origin rpy="0 0 0" xyz="0.01320633 0.00476708 0.00380534"></origin>
			<mass value="0.27621302"></mass>
			<inertia ixx="0.00017716" ixy="1.683e-05" ixz="-1.786e-05" iyy="0.00026787" iyz="2.62e-06" izz="0.00035728"></inertia>
		</inertial>
	</link>
	<link name="base">
		<visual>
			<origin rpy="0 0 0" xyz="0 0 0"></origin>
			<geometry>
				<box size="0.001 0.001 0.001"></box>
			</geometry>
		</visual>
	</link>
	<link name="trunk">
		<visual>
			<origin rpy="0 0 0" xyz="0 0 0"></origin>
			<geometry>
				<mesh filename="/home/chris/Desktop/awesome-loco-manipulation/robots/B1_Z1/meshes/trunkb.dae" scale="1 1 1"></mesh>
			</geometry>
			<material name="orange"></material>
		</visual>
		<collision>
			<geometry>
				<sphere radius="0.189077"></sphere>
			</geometry>
			<origin xyz="-0.16303226203822332 0.0038470882557377784 -0.0027652838939918913" rpy="0 0 0"></origin>
		</collision>
		<collision>
			<geometry>
				<sphere radius="0.193184"></sphere>
			</geometry>
			<origin xyz="0.009178737961776661 -0.008574911744262222 -0.0009592838939918927" rpy="0 0 0"></origin>
		</collision>
		<collision>
			<geometry>
				<sphere radius="0.16112"></sphere>
			</geometry>
			<origin xyz="0.18528473796177666 -0.023121911744262223 -0.014231283893991892" rpy="0 0 0"></origin>
		</collision>
		<collision>
			<geometry>
				<sphere radius="0.124831"></sphere>
			</geometry>
			<origin xyz="0.43694873796177663 -0.0016759117442622217 -0.045303283893991894" rpy="0 0 0"></origin>
		</collision>
		<collision>
			<geometry>
				<sphere radius="0.114827"></sphere>
			</geometry>
			<origin xyz="0.3896717379617767 -0.0014319117442622219 0.04521771610600811" rpy="0 0 0"></origin>
		</collision>
		<collision>
			<geometry>
				<sphere radius="0.118618"></sphere>
			</geometry>
			<origin xyz="-0.38964726203822336 0.0003750882557377782 -0.03235328389399189" rpy="0 0 0"></origin>
		</collision>
		<collision>
			<geometry>
				<sphere radius="0.114168"></sphere>
			</geometry>
			<origin xyz="-0.42850226203822334 -0.0016299117442622217 0.0614157161060081" rpy="0 0 0"></origin>
		</collision>
		<collision>
			<geometry>
				<sphere radius="0.149807"></sphere>
			</geometry>
			<origin xyz="0.15533673796177666 0.05178008825573778 -0.002711283893991891" rpy="0 0 0"></origin>
		</collision>
		<inertial>
			<origin rpy="0 0 0" xyz="0.008987 0.002243 0.003013"></origin>
			<mass value="29.45"></mass>
			<inertia ixx="0.183142146" ixy="-0.001379002" ixz="-0.027956055" iyy="0.756327752" iyz="0.000193774" izz="0.783777558"></inertia>
		</inertial>
	</link>
	<transmission name="JointTransGripper">
		<type>transmission_interface/SimpleTransmission</type>
		<joint name="jointGripper">
			<hardwareInterface>hardware_interface/EffortJointInterface</hardwareInterface>
		</joint>
		<actuator name="ActuatorGripper">
			<hardwareInterface>hardware_interface/EffortJointInterface</hardwareInterface>
			<mechanicalReduction>1</mechanicalReduction>
		</actuator>
	</transmission>
</robot>